Workbook
Name Slicer_category_name: #N/A
Name Slicer_video_type: #N/A
Name Slicer_Year_Month: #N/A

Sheet CategoryMap
A1: category_id | B1: category_name
A2: 1 | B2: Film & Animation
A3: 2 | B3: Autos & Vehicles
A4: 10 | B4: Music
A5: 15 | B5: Pets & Animals
A6: 17 | B6: Sports
A7: 19 | B7: Travel & Events
A8: 20 | B8: Gaming
A9: 22 | B9: People & Blogs
A10: 23 | B10: Comedy
A11: 24 | B11: Entertainment
A12: 25 | B12: News & Politics
A13: 26 | B13: Howto & Style
... A16: 29 | B16: Nonprofits & Activism

Sheet youtube_data
A1: video_id | B1: Title | C1: Description | D1: published_date | E1: Real Date | F1: Year | G1: Month | H1: Year_Month | I1: Days_Since_Published | J1: channel_id | K1: channel_title | L1: tags | M1: category_id | N1: category_name | O1: view_count | P1: like_count | Q1: comment_count | R1: engagement_rate | S1: duration_seconds | T1: video_type
A2: gsJAlLOFBv0 | B2: TINY Tech That Actually Works | C2: No description available | D2: 2025-05-02T17:37:10Z | E2: =DATEVALUE(LEFT(D2,10)) -> 45779 | F2: =YEAR(E2) -> 2025 | G2: =TEXT(E2,"MMMM") -> May | H2: =TEXT(E2,"YYYY-MM") -> 2025-05 | I2: =TODAY() - DATEVALUE(LEFT(D2,10)) -> 145 | J2: UCMiJRAwDNSNzuYeN2uWa0pA | K2: Mrwhosetheboss | L2: ['tiny', 'tech', 'gadgets', 'small', 'miniature'] | M2: 28 | N2: =VLOOKUP(M2, CategoryMap!$A$2:$B$100, 2, FALSE) -> Science & Technology | O2: 8962092 | P2: 243350 | Q2: 515 | R2: =IF(O2=0, 0, (P2 + Q2) / O2) -> 0.027210723 | S2: 57 | T2: =IF(S2<=60, "Short", "Long") -> Short
A3: ypicIkaiViM | B3: AI & future of workforce: Andr... | C3: Andrew Yang, Forward Party co-chair and former Dem... | D3: 2025-06-18T12:39:53Z | E3: =DATEVALUE(LEFT(D3,10)) -> 45826 | F3: =YEAR(E3) -> 2025 | G3: =TEXT(E3,"MMMM") -> June | H3: =TEXT(E3,"YYYY-MM") -> 2025-06 | I3: =TODAY() - DATEVALUE(LEFT(D3,10)) -> 98 | J3: UCrp_UI8XtuYfpiqluWLD7Lw | K3: CNBC Television | L3: ['Squawk Box U.S.', 'CNBC', 'business news', 'finance stock', 'stock market', 'news channel', 'news station', 'breaking news', 'us news', 'world news', 'cable', 'cable news', 'finance news', 'money', 'money tips', 'financial news', 'stock market news', 'stocks'] | M3: 25 | N3: =VLOOKUP(M3, CategoryMap!$A$2:$B$100, 2, FALSE) -> News & Politics | O3: 289626 | P3: 3393 | Q3: 1240 | R3: =IF(O3=0, 0, (P3 + Q3) / O3) -> 0.015996492 | S3: 470 | T3: =IF(S3<=60, "Short", "Long") -> Long
A4: 1Nef8LPO-jo | B4: 5 ILLEGAL gadgets that will ge... | C4: #shorts #technology I spend a LOT of time trying... | D4: 2022-11-01T11:00:06Z | E4: =DATEVALUE(LEFT(D4,10)) -> 44866 | F4: =YEAR(E4) -> 2022 | G4: =TEXT(E4,"MMMM") -> November | H4: =TEXT(E4,"YYYY-MM") -> 2022-11 | I4: =TODAY() - DATEVALUE(LEFT(D4,10)) -> 1058 | J4: UCMiJRAwDNSNzuYeN2uWa0pA | K4: Mrwhosetheboss | L4: ['shorts', 'tech'] | M4: 28 | N4: =VLOOKUP(M4, CategoryMap!$A$2:$B$100, 2, FALSE) -> Science & Technology | O4: 81372201 | P4: 4178447 | Q4: 6378 | R4: =IF(O4=0, 0, (P4 + Q4) / O4) -> 0.05142819 | S4: 47 | T4: =IF(S4<=60, "Short", "Long") -> Short
A5: lCHqmzynO-s | B5: Overrated vs. Underrated Tech | C5: ðŸ’¬ Join my Discord server: https://discord.gg/go... | D5: 2024-07-08T18:04:31Z | E5: =DATEVALUE(LEFT(D5,10)) -> 45481 | F5: =YEAR(E5) -> 2024 | G5: =TEXT(E5,"MMMM") -> July | H5: =TEXT(E5,"YYYY-MM") -> 2024-07 | I5: =TODAY() - DATEVALUE(LEFT(D5,10)) -> 443 | J5: UCPk2s5c4R_d-EUUNvFFODoA | K5: Gohar Khan | L5: ['thailand', 'surin', 'style', 'travel', 'day', 'asia', 'elephant', 'bangkok', 'elephantnature', 'asian', 'animal', 'wildlife', 'chiang', 'african', 'asia', 'park', 'safari', 'big', 'travel', 'minneriya', 'thailand grass', 'art', 'green', 'ivory', 'à¸Šà¹‰à¸²à¸‡', 'à¸—à¸­à¸‡à¹ƒà¸š', 'à¸žà¸¥à¸²à¸¢à¸—à¸­à¸‡à¹ƒà¸š', 'à¸«à¸™à¸¸à¹ˆà¸¡à¹€à¸ªà¸', 'à¹€à¸ªà¸', 'à¸«à¸™à¸¸à¹ˆà¹€à¸ªà¸', 'à¸žà¸¥à¸²à¸¢à¸«à¸™à¸¸à¹ˆà¸¡à¹€à¸ªà¸', 'à¸­à¸‡à¸„à¹Œà¸šà¸²à¸', 'à¸žà¸¥à¸²à¸¢à¸šà¸±à¸§à¸šà¸²à¸™', 'à¸šà¸±à¸§à¸šà¸²à¸™', 'à¸à¸­à¸¢à¸—à¸­à¸‡', 'à¸”à¸²à¸§à¸¡à¸‡à¸„à¸¥', 'banana'] | M5: 27 | N5: =VLOOKUP(M5, CategoryMap!$A$2:$B$100, 2, FALSE) -> Education | O5: 21255964 | P5: 909386 | Q5: 2681 | R5: =IF(O5=0, 0, (P5 + Q5) / O5) -> 0.042908757 | S5: 31 | T5: =IF(S5<=60, "Short", "Long") -> Short
A6: 7uFrtqSwYzM | B6: APPLE Glass Revolutionizes AR ... | C6: Discover the revolutionary world of augmented real... | D6: 2024-12-22T16:49:00Z | E6: =DATEVALUE(LEFT(D6,10)) -> 45648 | F6: =YEAR(E6) -> 2024 | G6: =TEXT(E6,"MMMM") -> December | H6: =TEXT(E6,"YYYY-MM") -> 2024-12 | I6: =TODAY() - DATEVALUE(LEFT(D6,10)) -> 276 | J6: UCxqG_E-68WAE0TWYfIopv6Q | K6: Digifix | L6: ['apple glasses price', 'apple glasses design', 'vr', 'apple glasses release date', 'apple vr', 'apple smart glasses', 'ar glasses', 'iglasses', 'apple glasses', 'virtual reality', 'apple ar glasses', 'apple glasses concept', 'apple glass price', 'augmented reality', 'apple glass review', 'apple glass', 'apple glasses leak', 'apple ar headset', 'best ar glasses', 'glasses', 'apple glass launch date', 'smart glasses'] | M6: 28 | N6: =VLOOKUP(M6, CategoryMap!$A$2:$B$100, 2, FALSE) -> Science & Technology | O6: 2790436 | P6: 44278 | Q6: 1359 | R6: =IF(O6=0, 0, (P6 + Q6) / O6) -> 0.016354792 | S6: 16 | T6: =IF(S6<=60, "Short", "Long") -> Short
A7: THw-wXt7wyM | B7: 5 Tech Myths Busted! | C7: #shorts I spend a LOT of time trying to make my ... | D7: 2022-10-02T19:40:14Z | E7: =DATEVALUE(LEFT(D7,10)) -> 44836 | F7: =YEAR(E7) -> 2022 | G7: =TEXT(E7,"MMMM") -> October | H7: =TEXT(E7,"YYYY-MM") -> 2022-10 | I7: =TODAY() - DATEVALUE(LEFT(D7,10)) -> 1088 | J7: UCMiJRAwDNSNzuYeN2uWa0pA | K7: Mrwhosetheboss | L7: ['shorts', 'tech', 'myths', 'busted', 'tips'] | M7: 28 | N7: =VLOOKUP(M7, CategoryMap!$A$2:$B$100, 2, FALSE) -> Science & Technology | O7: 28131104 | P7: 1956461 | Q7: 6253 | R7: =IF(O7=0, 0, (P7 + Q7) / O7) -> 0.069770244 | S7: 56 | T7: =IF(S7<=60, "Short", "Long") -> Short
A8: uvG-WToQfU4 | B8: Old Or New Technology? | C8: Follow me here: Instagram â–º https://www.instagra... | D8: 2024-07-17T19:15:02Z | E8: =DATEVALUE(LEFT(D8,10)) -> 45490 | F8: =YEAR(E8) -> 2024 | G8: =TEXT(E8,"MMMM") -> July | H8: =TEXT(E8,"YYYY-MM") -> 2024-07 | I8: =TODAY() - DATEVALUE(LEFT(D8,10)) -> 434 | J8: UCWBWgCD4oAqT3hUeq40SCUw | K8: Sambucha | L8: ['thailand', 'surin', 'style', 'travel', 'day', 'asia', 'elephant', 'bangkok', 'elephantnature', 'asian', 'animal', 'wildlife', 'chiang', 'african', 'asia', 'park', 'safari', 'big', 'travel', 'minneriya', 'thailand grass', 'art', 'green', 'ivory', 'à¸Šà¹‰à¸²à¸‡', 'à¸—à¸­à¸‡à¹ƒà¸š', 'à¸žà¸¥à¸²à¸¢à¸—à¸­à¸‡à¹ƒà¸š', 'à¸«à¸™à¸¸à¹ˆà¸¡à¹€à¸ªà¸', 'à¹€à¸ªà¸', 'à¸«à¸™à¸¸à¹ˆà¹€à¸ªà¸', 'à¸žà¸¥à¸²à¸¢à¸«à¸™à¸¸à¹ˆà¸¡à¹€à¸ªà¸', 'à¸­à¸‡à¸„à¹Œà¸šà¸²à¸', 'à¸žà¸¥à¸²à¸¢à¸šà¸±à¸§à¸šà¸²à¸™', 'à¸šà¸±à¸§à¸šà¸²à¸™', 'à¸à¸­à¸¢à¸—à¸­à¸‡', 'à¸”à¸²à¸§à¸¡à¸‡à¸„à¸¥', 'banana'] | M8: 24 | N8: =VLOOKUP(M8, CategoryMap!$A$2:$B$100, 2, FALSE) -> Entertainment | O8: 3736477 | P8: 246338 | Q8: 2504 | R8: =IF(O8=0, 0, (P8 + Q8) / O8) -> 0.066598028 | S8: 60 | T8: =IF(S8<=60, "Short", "Long") -> Short
A9: LZYfSYXY-go | B9: Appleâ€™s THINNEST ever device... | C9: #shorts #tech #gadgets #apple #iphone I spend a... | D9: 2024-01-04T15:32:23Z | E9: =DATEVALUE(LEFT(D9,10)) -> 45295 | F9: =YEAR(E9) -> 2024 | G9: =TEXT(E9,"MMMM") -> January | H9: =TEXT(E9,"YYYY-MM") -> 2024-01 | I9: =TODAY() - DATEVALUE(LEFT(D9,10)) -> 629 | J9: UCMiJRAwDNSNzuYeN2uWa0pA | K9: Mrwhosetheboss | L9: ['apple', 'iphone', 'tech', 'gadgets', 'shorts', 'thinnest', 'smallest'] | M9: 28 | N9: =VLOOKUP(M9, CategoryMap!$A$2:$B$100, 2, FALSE) -> Science & Technology | O9: 17538777 | P9: 835009 | Q9: 3583 | R9: =IF(O9=0, 0, (P9 + Q9) / O9) -> 0.047813596 | S9: 30 | T9: =IF(S9<=60, "Short", "Long") -> Short
A10: jYcV7a098Yw | B10: Chinese Technology is LEADING ... | C10: Chinese Technology is LEADING the World - SNEC 202... | D10: 2025-06-19T10:07:23Z | E10: =DATEVALUE(LEFT(D10,10)) -> 45827 | F10: =YEAR(E10) -> 2025 | G10: =TEXT(E10,"MMMM") -> June | H10: =TEXT(E10,"YYYY-MM") -> 2025-06 | I10: =TODAY() - DATEVALUE(LEFT(D10,10)) -> 97 | J10: UCzDE2LGSmJnw53WrZ7mM_Aw | K10: Living in China | L10: ['midea', 'living in china', 'china energy', 'midea technology', 'china technology', 'midea energy', 'smart ac', 'midea ac review', 'kuka', 'kuka robot', 'air conditioner', 'midea air conditioner', 'hiconics', 'clou electronics', 'china tech', 'china', 'china life', 'jason lightfoot', 'china travel', 'china tariffs'] | M10: 19 | N10: =VLOOKUP(M10, CategoryMap!$A$2:$B$100, 2, FALSE) -> Travel & Events | O10: 17265 | P10: 1569 | Q10: 103 | R10: =IF(O10=0, 0, (P10 + Q10) / O10) -> 0.096843325 | S10: 437 | T10: =IF(S10<=60, "Short", "Long") -> Long
A11: 5fKkXFresYI | B11: 5 Times Tech has SAVED LIVES! | C11: #shorts #technology I spend a LOT of time trying... | D11: 2022-10-15T08:25:08Z | E11: =DATEVALUE(LEFT(D11,10)) -> 44849 | F11: =YEAR(E11) -> 2022 | G11: =TEXT(E11,"MMMM") -> October | H11: =TEXT(E11,"YYYY-MM") -> 2022-10 | I11: =TODAY() - DATEVALUE(LEFT(D11,10)) -> 1075 | J11: UCMiJRAwDNSNzuYeN2uWa0pA | K11: Mrwhosetheboss | L11: ['tech', 'shorts'] | M11: 28 | N11: =VLOOKUP(M11, CategoryMap!$A$2:$B$100, 2, FALSE) -> Science & Technology | O11: 41043500 | P11: 2647228 | Q11: 8379 | R11: =IF(O11=0, 0, (P11 + Q11) / O11) -> 0.064702255 | S11: 60 | T11: =IF(S11<=60, "Short", "Long") -> Short
A12: TaY-jRMbNpk | B12: Huawei Mate XT Hands On! ðŸ”¥ | C12: Huawei Mate XT Hands On! ðŸ”¥ #huaweimatext #hua... | D12: 2024-09-29T13:28:57Z | E12: =DATEVALUE(LEFT(D12,10)) -> 45564 | F12: =YEAR(E12) -> 2024 | G12: =TEXT(E12,"MMMM") -> September | H12: =TEXT(E12,"YYYY-MM") -> 2024-09 | I12: =TODAY() - DATEVALUE(LEFT(D12,10)) -> 360 | J12: UCXy9a8QpkHVsvAXXaQavx2g | K12: We Tech | L12: ['huawei mate xt', 'huawei mate xt review', 'Huawei mate xt unboxing', 'huawei mate xt hands on', 'huawei', 'we tech', 'New', 'trending', 'technology', 'folding'] | M12: 28 | N12: =VLOOKUP(M12, CategoryMap!$A$2:$B$100, 2, FALSE) -> Science & Technology | O12: 8207184 | P12: 168522 | Q12: 882 | R12: =IF(O12=0, 0, (P12 + Q12) / O12) -> 0.020640941 | S12: 16 | T12: =IF(S12<=60, "Short", "Long") -> Short
A13: pKbr1LhfxXM | B13: Worlds smallest 4K headset ðŸ˜... | C13: Visor is the world's smallest 4K headset. Spawn fi... | D13: 2024-08-15T04:59:00Z | E13: =DATEVALUE(LEFT(D13,10)) -> 45519 | F13: =YEAR(E13) -> 2024 | G13: =TEXT(E13,"MMMM") -> August | H13: =TEXT(E13,"YYYY-MM") -> 2024-08 | I13: =TODAY() - DATEVALUE(LEFT(D13,10)) -> 405 | J13: UCGmuLwV0XD_uqL4wKZg4hgA | K13: Immersed | L13: ['thailand', 'surin', 'style', 'travel', 'day', 'asia', 'elephant', 'bangkok', 'elephantnature', 'asian', 'animal', 'wildlife', 'chiang', 'african', 'asia', 'park', 'safari', 'big', 'travel', 'minneriya', 'thailand grass', 'art', 'green', 'ivory', 'à¸Šà¹‰à¸²à¸‡', 'à¸—à¸­à¸‡à¹ƒà¸š', 'à¸žà¸¥à¸²à¸¢à¸—à¸­à¸‡à¹ƒà¸š', 'à¸«à¸™à¸¸à¹ˆà¸¡à¹€à¸ªà¸', 'à¹€à¸ªà¸', 'à¸«à¸™à¸¸à¹ˆà¹€à¸ªà¸', 'à¸žà¸¥à¸²à¸¢à¸«à¸™à¸¸à¹ˆà¸¡à¹€à¸ªà¸', 'à¸­à¸‡à¸„à¹Œà¸šà¸²à¸', 'à¸žà¸¥à¸²à¸¢à¸šà¸±à¸§à¸šà¸²à¸™', 'à¸šà¸±à¸§à¸šà¸²à¸™', 'à¸à¸­à¸¢à¸—à¸­à¸‡', 'à¸”à¸²à¸§à¸¡à¸‡à¸„à¸¥', 'banana'] | M13: 28 | N13: =VLOOKUP(M13, CategoryMap!$A$2:$B$100, 2, FALSE) -> Science & Technology | O13: 24573162 | P13: 413243 | Q13: 297 | R13: =IF(O13=0, 0, (P13 + Q13) / O13) -> 0.016828929 | S13: 15 | T13: =IF(S13<=60, "Short", "Long") -> Short
... A299: YUvf1OILS1I | B299: WWDC 2025 - Rating every new A... | C299: My review of WWDC 2025! All the updates coming to ... | D299: 2025-06-10T03:31:02Z | E299: =DATEVALUE(LEFT(D299,10)) -> 45818 | F299: =YEAR(E299) -> 2025 | G299: =TEXT(E299,"MMMM") -> June | H299: =TEXT(E299,"YYYY-MM") -> 2025-06 | I299: =TODAY() - DATEVALUE(LEFT(D299,10)) -> 106 | J299: UCMiJRAwDNSNzuYeN2uWa0pA | K299: Mrwhosetheboss | L299: ['wwdc', 'wwdc 25', 'wwdc 2025', 'ios 26', 'iphone', 'apple', 'mac os', 'ios', 'mac os 26'] | M299: 28 | N299: =VLOOKUP(M299, CategoryMap!$A$2:$B$100, 2, FALSE) -> Science & Technology | O299: 2359964 | P299: 76764 | Q299: 4946 | R299: =IF(O299=0, 0, (P299 + Q299) / O299) -> 0.03462341 | S299: 1002 | T299: =IF(S299<=60, "Short", "Long") -> Long
A300: #NAME? | B300: Why You Shouldn't Cook on a We... | C300: This video explains why certain stones can crack o... | D300: 2025-06-19T13:51:13Z | E300: =DATEVALUE(LEFT(D300,10)) -> 45827 | F300: =YEAR(E300) -> 2025 | G300: =TEXT(E300,"MMMM") -> June | H300: =TEXT(E300,"YYYY-MM") -> 2025-06 | I300: =TODAY() - DATEVALUE(LEFT(D300,10)) -> 97 | J300: UCJAliJPtOljSberbNEnUF5A | K300: QuickTechNow | L300: ['thailand', 'surin', 'style', 'travel', 'day', 'asia', 'elephant', 'bangkok', 'elephantnature', 'asian', 'animal', 'wildlife', 'chiang', 'african', 'asia', 'park', 'safari', 'big', 'travel', 'minneriya', 'thailand grass', 'art', 'green', 'ivory', 'à¸Šà¹‰à¸²à¸‡', 'à¸—à¸­à¸‡à¹ƒà¸š', 'à¸žà¸¥à¸²à¸¢à¸—à¸­à¸‡à¹ƒà¸š', 'à¸«à¸™à¸¸à¹ˆà¸¡à¹€à¸ªà¸', 'à¹€à¸ªà¸', 'à¸«à¸™à¸¸à¹ˆà¹€à¸ªà¸', 'à¸žà¸¥à¸²à¸¢à¸«à¸™à¸¸à¹ˆà¸¡à¹€à¸ªà¸', 'à¸­à¸‡à¸„à¹Œà¸šà¸²à¸', 'à¸žà¸¥à¸²à¸¢à¸šà¸±à¸§à¸šà¸²à¸™', 'à¸šà¸±à¸§à¸šà¸²à¸™', 'à¸à¸­à¸¢à¸—à¸­à¸‡', 'à¸”à¸²à¸§à¸¡à¸‡à¸„à¸¥', 'banana'] | M300: 22 | N300: =VLOOKUP(M300, CategoryMap!$A$2:$B$100, 2, FALSE) -> People & Blogs | O300: 32968 | P300: 345 | Q300: 0 | R300: =IF(O300=0, 0, (P300 + Q300) / O300) -> 0.010464693 | S300: 24 | T300: =IF(S300<=60, "Short", "Long") -> Short
A301: hz6oys4Eem4 | B301: Apple's AI Crisis: Explained! | C301: Apple Intelligence Delays are either no big deal o... | D301: 2025-03-29T02:41:29Z | E301: =DATEVALUE(LEFT(D301,10)) -> 45745 | F301: =YEAR(E301) -> 2025 | G301: =TEXT(E301,"MMMM") -> March | H301: =TEXT(E301,"YYYY-MM") -> 2025-03 | I301: =TODAY() - DATEVALUE(LEFT(D301,10)) -> 179 | J301: UCBJycsmduvYEL83R_U4JriQ | K301: Marques Brownlee | L301: ['Apple AI', 'Apple Intelligence', 'MKBHD'] | M301: 28 | N301: =VLOOKUP(M301, CategoryMap!$A$2:$B$100, 2, FALSE) -> Science & Technology | O301: 7339248 | P301: 194778 | Q301: 14438 | R301: =IF(O301=0, 0, (P301 + Q301) / O301) -> 0.028506463 | S301: 1012 | T301: =IF(S301<=60, "Short", "Long") -> Long
A302: 9JCsox7C7ew | B302: Electric Crossing Gate â€¢ Dc ... | C302: Electric Crossing Gate â€¢ Dc Motor | #tech #short... | D302: 2025-01-25T04:40:09Z | E302: =DATEVALUE(LEFT(D302,10)) -> 45682 | F302: =YEAR(E302) -> 2025 | G302: =TEXT(E302,"MMMM") -> January | H302: =TEXT(E302,"YYYY-MM") -> 2025-01 | I302: =TODAY() - DATEVALUE(LEFT(D302,10)) -> 242 | J302: UCWOWcJqL16b5ZK0bU-mO20A | K302: Digital Smart Idea | L302: ['dc motor project', 'dc motor project easy', 'dc motor project free energy', 'Electric Crossing Gate', 'Dc Motor', 'shorts video', 'dc motor project shorts', 'dc motor project ideas'] | M302: 28 | N302: =VLOOKUP(M302, CategoryMap!$A$2:$B$100, 2, FALSE) -> Science & Technology | O302: 20936016 | P302: 217464.61 | Q302: 24 | R302: =IF(O302=0, 0, (P302 + Q302) / O302) -> 0.010388252 | S302: 6 | T302: =IF(S302<=60, "Short", "Long") -> Short
A303: 07OQ1uQ4-do | B303: Apple Vision Pro à¤¸à¤¬à¤¸à¥‡ ... | C303: Apple Vision Pro à¤¸à¤¬à¤¸à¥‡ à¤®à¤¹à¤‚à¤—à¤¾ à¤šà... | D303: 2024-02-07T13:00:00Z | E303: =DATEVALUE(LEFT(D303,10)) -> 45329 | F303: =YEAR(E303) -> 2024 | G303: =TEXT(E303,"MMMM") -> February | H303: =TEXT(E303,"YYYY-MM") -> 2024-02 | I303: =TODAY() - DATEVALUE(LEFT(D303,10)) -> 595 | J303: UCglXlpWjIi95auM3umWWLdw | K303: Tech Master Shorts | L303: ['tech master', 'shorts', 'technology', 'apple', 'visionpro', 'expensivegadget', 'new apple product', 'trending gadget', 'dubai', 'unboxing', 'fun tech', 'visionpro2024', 'apple product'] | M303: 28 | N303: =VLOOKUP(M303, CategoryMap!$A$2:$B$100, 2, FALSE) -> Science & Technology | O303: 4473021 | P303: 257456 | Q303: 406 | R303: =IF(O303=0, 0, (P303 + Q303) / O303) -> 0.057648287 | S303: 51 | T303: =IF(S303<=60, "Short", "Long") -> Short
A304: doJMDPCyl7A | B304: respect ðŸ˜±ðŸ”¥ I non stop cy... | C304: No description available | D304: 2024-04-13T13:47:23Z | E304: =DATEVALUE(LEFT(D304,10)) -> 45395 | F304: =YEAR(E304) -> 2024 | G304: =TEXT(E304,"MMMM") -> April | H304: =TEXT(E304,"YYYY-MM") -> 2024-04 | I304: =TODAY() - DATEVALUE(LEFT(D304,10)) -> 529 | J304: UCB2VRihXTrkzL5ifI1BlPVw | K304: Rishiexperiment_18 | L304: ['thailand', 'surin', 'style', 'travel', 'day', 'asia', 'elephant', 'bangkok', 'elephantnature', 'asian', 'animal', 'wildlife', 'chiang', 'african', 'asia', 'park', 'safari', 'big', 'travel', 'minneriya', 'thailand grass', 'art', 'green', 'ivory', 'à¸Šà¹‰à¸²à¸‡', 'à¸—à¸­à¸‡à¹ƒà¸š', 'à¸žà¸¥à¸²à¸¢à¸—à¸­à¸‡à¹ƒà¸š', 'à¸«à¸™à¸¸à¹ˆà¸¡à¹€à¸ªà¸', 'à¹€à¸ªà¸', 'à¸«à¸™à¸¸à¹ˆà¹€à¸ªà¸', 'à¸žà¸¥à¸²à¸¢à¸«à¸™à¸¸à¹ˆà¸¡à¹€à¸ªà¸', 'à¸­à¸‡à¸„à¹Œà¸šà¸²à¸', 'à¸žà¸¥à¸²à¸¢à¸šà¸±à¸§à¸šà¸²à¸™', 'à¸šà¸±à¸§à¸šà¸²à¸™', 'à¸à¸­à¸¢à¸—à¸­à¸‡', 'à¸”à¸²à¸§à¸¡à¸‡à¸„à¸¥', 'banana'] | M304: 28 | N304: =VLOOKUP(M304, CategoryMap!$A$2:$B$100, 2, FALSE) -> Science & Technology | O304: 28700120 | P304: 217464.61 | Q304: 1460 | R304: =IF(O304=0, 0, (P304 + Q304) / O304) -> 0.0076280032 | S304: 14 | T304: =IF(S304<=60, "Short", "Long") -> Short
A305: ucbgAS-M-A8 | B305: Museum Exhibit Reveals Enginee... | C305: Explore the fascinating world of engineering and m... | D305: 2025-06-20T22:51:57Z | E305: =DATEVALUE(LEFT(D305,10)) -> 45828 | F305: =YEAR(E305) -> 2025 | G305: =TEXT(E305,"MMMM") -> June | H305: =TEXT(E305,"YYYY-MM") -> 2025-06 | I305: =TODAY() - DATEVALUE(LEFT(D305,10)) -> 96 | J305: UC-4Jx7yjLemePx2JFN9UbyA | K305: IoT Forge | L305: ['thailand', 'surin', 'style', 'travel', 'day', 'asia', 'elephant', 'bangkok', 'elephantnature', 'asian', 'animal', 'wildlife', 'chiang', 'african', 'asia', 'park', 'safari', 'big', 'travel', 'minneriya', 'thailand grass', 'art', 'green', 'ivory', 'à¸Šà¹‰à¸²à¸‡', 'à¸—à¸­à¸‡à¹ƒà¸š', 'à¸žà¸¥à¸²à¸¢à¸—à¸­à¸‡à¹ƒà¸š', 'à¸«à¸™à¸¸à¹ˆà¸¡à¹€à¸ªà¸', 'à¹€à¸ªà¸', 'à¸«à¸™à¸¸à¹ˆà¹€à¸ªà¸', 'à¸žà¸¥à¸²à¸¢à¸«à¸™à¸¸à¹ˆà¸¡à¹€à¸ªà¸', 'à¸­à¸‡à¸„à¹Œà¸šà¸²à¸', 'à¸žà¸¥à¸²à¸¢à¸šà¸±à¸§à¸šà¸²à¸™', 'à¸šà¸±à¸§à¸šà¸²à¸™', 'à¸à¸­à¸¢à¸—à¸­à¸‡', 'à¸”à¸²à¸§à¸¡à¸‡à¸„à¸¥', 'banana'] | M305: 28 | N305: =VLOOKUP(M305, CategoryMap!$A$2:$B$100, 2, FALSE) -> Science & Technology | O305: 476 | P305: 2 | Q305: 0 | R305: =IF(O305=0, 0, (P305 + Q305) / O305) -> 0.0042016807 | S305: 20 | T305: =IF(S305<=60, "Short", "Long") -> Short
A306: 6bSXorhy_eQ | B306: unknown planet ðŸ˜² 3d Special... | C306: No description available | D306: 2022-08-15T01:22:05Z | E306: =DATEVALUE(LEFT(D306,10)) -> 44788 | F306: =YEAR(E306) -> 2022 | G306: =TEXT(E306,"MMMM") -> August | H306: =TEXT(E306,"YYYY-MM") -> 2022-08 | I306: =TODAY() - DATEVALUE(LEFT(D306,10)) -> 1136 | J306: UCOvOXLATfCrOJmAYaO4mRBA | K306: VFX HD | L306: ['thailand', 'surin', 'style', 'travel', 'day', 'asia', 'elephant', 'bangkok', 'elephantnature', 'asian', 'animal', 'wildlife', 'chiang', 'african', 'asia', 'park', 'safari', 'big', 'travel', 'minneriya', 'thailand grass', 'art', 'green', 'ivory', 'à¸Šà¹‰à¸²à¸‡', 'à¸—à¸­à¸‡à¹ƒà¸š', 'à¸žà¸¥à¸²à¸¢à¸—à¸­à¸‡à¹ƒà¸š', 'à¸«à¸™à¸¸à¹ˆà¸¡à¹€à¸ªà¸', 'à¹€à¸ªà¸', 'à¸«à¸™à¸¸à¹ˆà¹€à¸ªà¸', 'à¸žà¸¥à¸²à¸¢à¸«à¸™à¸¸à¹ˆà¸¡à¹€à¸ªà¸', 'à¸­à¸‡à¸„à¹Œà¸šà¸²à¸', 'à¸žà¸¥à¸²à¸¢à¸šà¸±à¸§à¸šà¸²à¸™', 'à¸šà¸±à¸§à¸šà¸²à¸™', 'à¸à¸­à¸¢à¸—à¸­à¸‡', 'à¸”à¸²à¸§à¸¡à¸‡à¸„à¸¥', 'banana'] | M306: 1 | N306: =VLOOKUP(M306, CategoryMap!$A$2:$B$100, 2, FALSE) -> Film & Animation | O306: 4006570 | P306: 45260 | Q306: 184 | R306: =IF(O306=0, 0, (P306 + Q306) / O306) -> 0.01134237 | S306: 12 | T306: =IF(S306<=60, "Short", "Long") -> Short
A307: yJSrX1uOjxs | B307: This Breakthrough Technology W... | C307: ðŸ‘‰ Grab your free seat to the 2-Day AI Mastermin... | D307: 2025-06-12T16:36:41Z | E307: =DATEVALUE(LEFT(D307,10)) -> 45820 | F307: =YEAR(E307) -> 2025 | G307: =TEXT(E307,"MMMM") -> June | H307: =TEXT(E307,"YYYY-MM") -> 2025-06 | I307: =TODAY() - DATEVALUE(LEFT(D307,10)) -> 104 | J307: UCORX3Cl7ByidjEgzSCgv9Yw | K307: Anastasi In Tech | L307: ['graphene', 'new graphene chip', 'light based chip', 'photonic chip', 'processor', 'new computer'] | M307: 27 | N307: =VLOOKUP(M307, CategoryMap!$A$2:$B$100, 2, FALSE) -> Education | O307: 287788 | P307: 16726 | Q307: 887 | R307: =IF(O307=0, 0, (P307 + Q307) / O307) -> 0.061201301 | S307: 1158 | T307: =IF(S307<=60, "Short", "Long") -> Long
A308: qndVx4jOxz8 | B308: Robots New Technology #robots ... | C308: Robots New Technology #robots #shorts #science "... | D308: 2025-01-28T13:01:12Z | E308: =DATEVALUE(LEFT(D308,10)) -> 45685 | F308: =YEAR(E308) -> 2025 | G308: =TEXT(E308,"MMMM") -> January | H308: =TEXT(E308,"YYYY-MM") -> 2025-01 | I308: =TODAY() - DATEVALUE(LEFT(D308,10)) -> 239 | J308: UCiMCEBZ4QMZlFcSULgrJ9vg | K308: it's robots | L308: ['#robots', '#shorts', '#science'] | M308: 28 | N308: =VLOOKUP(M308, CategoryMap!$A$2:$B$100, 2, FALSE) -> Science & Technology | O308: 3245054 | P308: 217464.61 | Q308: 498 | R308: =IF(O308=0, 0, (P308 + Q308) / O308) -> 0.067167637 | S308: 9 | T308: =IF(S308<=60, "Short", "Long") -> Short
A309: b2_rzbGibpo | B309: â‚¹4000000 à¤•à¤¾ Apple Vs Sup... | C309: 2000rs. Apple cloth vs 100rs. super clean jelly co... | D309: 2024-03-12T14:15:02Z | E309: =DATEVALUE(LEFT(D309,10)) -> 45363 | F309: =YEAR(E309) -> 2024 | G309: =TEXT(E309,"MMMM") -> March | H309: =TEXT(E309,"YYYY-MM") -> 2024-03 | I309: =TODAY() - DATEVALUE(LEFT(D309,10)) -> 561 | J309: UCglXlpWjIi95auM3umWWLdw | K309: Tech Master Shorts | L309: ['youtube shorts', 'youtube shorts video', 'best shorts', '#shorts', 'shorts', 'apple iphone #shorts', 'apple #shorts', 'dance short video', 'super cleaner', 'gadgets #short', 'shorts video', 'comparison', 'smartphone short video'] | M309: 28 | N309: =VLOOKUP(M309, CategoryMap!$A$2:$B$100, 2, FALSE) -> Science & Technology | O309: 17888444 | P309: 709022 | Q309: 5800 | R309: =IF(O309=0, 0, (P309 + Q309) / O309) -> 0.039959988 | S309: 58 | T309: =IF(S309<=60, "Short", "Long") -> Short
A310: hUbKhUBs6XI | B310: The mechanical switch is dead. | C310: Check prices on Amazon below Monsgeek FUN60 TMR: h... | D310: 2025-06-14T12:52:12Z | E310: =DATEVALUE(LEFT(D310,10)) -> 45822 | F310: =YEAR(E310) -> 2025 | G310: =TEXT(E310,"MMMM") -> June | H310: =TEXT(E310,"YYYY-MM") -> 2025-06 | I310: =TODAY() - DATEVALUE(LEFT(D310,10)) -> 102 | J310: UCRYOj4DmyxhBVrdvbsUwmAA | K310: optimum | L310: ['hall effect keyboard', 'best gaming keyboard', 'wooting', 'wooting 60HE', 'rapid trigger keyboard', 'optimum tech', 'optimum keyboard', 'razer vs wooting', 'snap tap', 'best keyboard for valorant'] | M310: 28 | N310: =VLOOKUP(M310, CategoryMap!$A$2:$B$100, 2, FALSE) -> Science & Technology | O310: 419707 | P310: 19816 | Q310: 2192 | R310: =IF(O310=0, 0, (P310 + Q310) / O310) -> 0.052436581 | S310: 880 | T310: =IF(S310<=60, "Short", "Long") -> Long
A311: 9_wcmArr_u0 | B311: nokia type c jack replace tips... | C311: No description available | D311: 2025-06-13T15:27:01Z | E311: =DATEVALUE(LEFT(D311,10)) -> 45821 | F311: =YEAR(E311) -> 2025 | G311: =TEXT(E311,"MMMM") -> June | H311: =TEXT(E311,"YYYY-MM") -> 2025-06 | I311: =TODAY() - DATEVALUE(LEFT(D311,10)) -> 103 | J311: UCVLaRbKaPFM29W91sHhGtqQ | K311: DKP REPAIR | L311: ['thailand', 'surin', 'style', 'travel', 'day', 'asia', 'elephant', 'bangkok', 'elephantnature', 'asian', 'animal', 'wildlife', 'chiang', 'african', 'asia', 'park', 'safari', 'big', 'travel', 'minneriya', 'thailand grass', 'art', 'green', 'ivory', 'à¸Šà¹‰à¸²à¸‡', 'à¸—à¸­à¸‡à¹ƒà¸š', 'à¸žà¸¥à¸²à¸¢à¸—à¸­à¸‡à¹ƒà¸š', 'à¸«à¸™à¸¸à¹ˆà¸¡à¹€à¸ªà¸', 'à¹€à¸ªà¸', 'à¸«à¸™à¸¸à¹ˆà¹€à¸ªà¸', 'à¸žà¸¥à¸²à¸¢à¸«à¸™à¸¸à¹ˆà¸¡à¹€à¸ªà¸', 'à¸­à¸‡à¸„à¹Œà¸šà¸²à¸', 'à¸žà¸¥à¸²à¸¢à¸šà¸±à¸§à¸šà¸²à¸™', 'à¸šà¸±à¸§à¸šà¸²à¸™', 'à¸à¸­à¸¢à¸—à¸­à¸‡', 'à¸”à¸²à¸§à¸¡à¸‡à¸„à¸¥', 'banana'] | M311: 28 | N311: =VLOOKUP(M311, CategoryMap!$A$2:$B$100, 2, FALSE) -> Science & Technology | O311: 21724 | P311: 377 | Q311: 4 | R311: =IF(O311=0, 0, (P311 + Q311) / O311) -> 0.017538207 | S311: 58 | T311: =IF(S311<=60, "Short", "Long") -> Short
A312: _qSmAtGPmrE | B312: Sim Connector Repair Tips #sho... | C312: No description available | D312: 2025-06-19T15:27:00Z | E312: =DATEVALUE(LEFT(D312,10)) -> 45827 | F312: =YEAR(E312) -> 2025 | G312: =TEXT(E312,"MMMM") -> June | H312: =TEXT(E312,"YYYY-MM") -> 2025-06 | I312: =TODAY() - DATEVALUE(LEFT(D312,10)) -> 97 | J312: UCVLaRbKaPFM29W91sHhGtqQ | K312: DKP REPAIR | L312: ['thailand', 'surin', 'style', 'travel', 'day', 'asia', 'elephant', 'bangkok', 'elephantnature', 'asian', 'animal', 'wildlife', 'chiang', 'african', 'asia', 'park', 'safari', 'big', 'travel', 'minneriya', 'thailand grass', 'art', 'green', 'ivory', 'à¸Šà¹‰à¸²à¸‡', 'à¸—à¸­à¸‡à¹ƒà¸š', 'à¸žà¸¥à¸²à¸¢à¸—à¸­à¸‡à¹ƒà¸š', 'à¸«à¸™à¸¸à¹ˆà¸¡à¹€à¸ªà¸', 'à¹€à¸ªà¸', 'à¸«à¸™à¸¸à¹ˆà¹€à¸ªà¸', 'à¸žà¸¥à¸²à¸¢à¸«à¸™à¸¸à¹ˆà¸¡à¹€à¸ªà¸', 'à¸­à¸‡à¸„à¹Œà¸šà¸²à¸', 'à¸žà¸¥à¸²à¸¢à¸šà¸±à¸§à¸šà¸²à¸™', 'à¸šà¸±à¸§à¸šà¸²à¸™', 'à¸à¸­à¸¢à¸—à¸­à¸‡', 'à¸”à¸²à¸§à¸¡à¸‡à¸„à¸¥', 'banana'] | M312: 28 | N312: =VLOOKUP(M312, CategoryMap!$A$2:$B$100, 2, FALSE) -> Science & Technology | O312: 11342 | P312: 282 | Q312: 3 | R312: =IF(O312=0, 0, (P312 + Q312) / O312) -> 0.025127843 | S312: 56 | T312: =IF(S312<=60, "Short", "Long") -> Short
... A514: hjDPKRXv-LU | B514: Life in 2100 (à¤­à¤µà¤¿à¤·à¥à... | C514: #Future #Technology #World #2100 #futuristic #sci-... | D514: 2024-08-08T13:50:25Z | E514: =DATEVALUE(LEFT(D514,10)) -> 45512 | F514: =YEAR(E514) -> 2024 | G514: =TEXT(E514,"MMMM") -> August | H514: =TEXT(E514,"YYYY-MM") -> 2024-08 | I514: =TODAY() - DATEVALUE(LEFT(D514,10)) -> 412 | J514: UCENLJimUiMr6Lo0shZ1Vq_A | K514: The Knowledge | L514: ['future technology', 'future world', 'world in 2100', 'futuristic', 'sci-fi', 'science fiction', 'future predictions', 'future life', 'future of humanity', 'future of earth', 'future tech', 'artificial intelligence', 'robotics', 'virtual reality', 'augmented reality', 'space exploration', 'sustainable energy', 'smart cities', 'bioengineering', 'nanotechnology', 'future society', 'climate change', 'overpopulation', 'social issues in 2100', 'future jobs', 'education in 2100', 'healthcare in 2100', 'transportation in 2100'] | M514: 27 | N514: =VLOOKUP(M514, CategoryMap!$A$2:$B$100, 2, FALSE) -> Education | O514: 587614 | P514: 8504 | Q514: 738 | R514: =IF(O514=0, 0, (P514 + Q514) / O514) -> 0.015728012 | S514: 752 | T514: =IF(S514<=60, "Short", "Long") -> Long
A515: #NAME? | B515: We Survived 100 Days In SKYBLO... | C515: â—INSTAGRAM! https://instagram.com/lordngaming?ig... | D515: 2024-08-24T09:28:40Z | E515: =DATEVALUE(LEFT(D515,10)) -> 45528 | F515: =YEAR(E515) -> 2024 | G515: =TEXT(E515,"MMMM") -> August | H515: =TEXT(E515,"YYYY-MM") -> 2024-08 | I515: =TODAY() - DATEVALUE(LEFT(D515,10)) -> 396 | J515: UCnaXMR7Tu3bj8cJ1ZzgcCTQ | K515: LordN Gaming | L515: ['Hardest skyblock', 'Skyblock timelapse', 'The nothing skyblock', 'Can you beat skyblock with nothing', 'LordJon25', 'Lordn gaming', 'lordn 100 days', 'skyblock with nothing', 'nothing skyblock', 'we survived 300 days in skyblock without tree in minecraft hardcore', 'Lordn 100 days skyblock', 'Minecraft skyblock without tree', 'we survived 100 days in skyblock minecraft', 'We survived 100 days in minecraft skyblock with nothing', 'Skyblock with nothing minecraft', 'Minecraft oneblock 100 days', 'Oneblock 100'] | M515: 20 | N515: =VLOOKUP(M515, CategoryMap!$A$2:$B$100, 2, FALSE) -> Gaming | O515: 413270 | P515: 7744 | Q515: 294 | R515: =IF(O515=0, 0, (P515 + Q515) / O515) -> 0.019449754 | S515: 1164 | T515: =IF(S515<=60, "Short", "Long") -> Long
A516: nkDJM3Z8bmk | B516: Innovative Healthcare: The Syn... | C516: What does it take to truly transform healthcare? I... | D516: 2025-05-28T16:12:58Z | E516: =DATEVALUE(LEFT(D516,10)) -> 45805 | F516: =YEAR(E516) -> 2025 | G516: =TEXT(E516,"MMMM") -> May | H516: =TEXT(E516,"YYYY-MM") -> 2025-05 | I516: =TODAY() - DATEVALUE(LEFT(D516,10)) -> 119 | J516: UCUI9vm69ZbAqRK3q3vKLWCQ | K516: Mint | L516: ['Mint', 'Mint News', 'Live Mint', 'Business News', 'News', 'Today News'] | M516: 25 | N516: =VLOOKUP(M516, CategoryMap!$A$2:$B$100, 2, FALSE) -> News & Politics | O516: 120483 | P516: 24 | Q516: 2 | R516: =IF(O516=0, 0, (P516 + Q516) / O516) -> 0.00021579808 | S516: 2687 | T516: =IF(S516<=60, "Short", "Long") -> Long
A517: RR0bLaOGEKc | B517: Bajaj Freedom 125 #bike #short... | C517: #bajaj #freedom #motorcycle #cng #and #petrol | D517: 2025-05-01T11:28:36Z | E517: =DATEVALUE(LEFT(D517,10)) -> 45778 | F517: =YEAR(E517) -> 2025 | G517: =TEXT(E517,"MMMM") -> May | H517: =TEXT(E517,"YYYY-MM") -> 2025-05 | I517: =TODAY() - DATEVALUE(LEFT(D517,10)) -> 146 | J517: UC8XyjHCZxoNa0h8xvgKw36Q | K517: W.A. | L517: ['Bajaj', 'Freedom', 'CNG', 'Petrol', 'Motorcycle'] | M517: 2 | N517: =VLOOKUP(M517, CategoryMap!$A$2:$B$100, 2, FALSE) -> Autos & Vehicles | O517: 4521 | P517: 48 | Q517: 0 | R517: =IF(O517=0, 0, (P517 + Q517) / O517) -> 0.01061712 | S517: 28 | T517: =IF(S517<=60, "Short", "Long") -> Short
A518: dKckaE9S5yo | B518: Alcatel Phone comeback in Indi... | C518: Alcatel V3 Ultra unboxing & quick review #Alcatel... | D518: 2025-06-07T14:31:35Z | E518: =DATEVALUE(LEFT(D518,10)) -> 45815 | F518: =YEAR(E518) -> 2025 | G518: =TEXT(E518,"MMMM") -> June | H518: =TEXT(E518,"YYYY-MM") -> 2025-06 | I518: =TODAY() - DATEVALUE(LEFT(D518,10)) -> 109 | J518: UC1tVU8H153ZFO9eRsxdJlhA | K518: Technology Gyan | L518: ['Alcatel phone', 'alcatel v3 ultra unboxing', 'alcatel v3 ultra camera', 'alcatel v3 ultra bgmi tes', 'alcatel v3 ultra price', 'alcatel v3 ultra'] | M518: 28 | N518: =VLOOKUP(M518, CategoryMap!$A$2:$B$100, 2, FALSE) -> Science & Technology | O518: 379513 | P518: 17123 | Q518: 1002 | R518: =IF(O518=0, 0, (P518 + Q518) / O518) -> 0.047758575 | S518: 631 | T518: =IF(S518<=60, "Short", "Long") -> Long
A519: aTdDvrf79TA | B519: vivo T4 Ultra Unboxing & First... | C519: Doston aaj ke video me hum unbox kar rahe hain all... | D519: 2025-06-11T06:30:00Z | E519: =DATEVALUE(LEFT(D519,10)) -> 45819 | F519: =YEAR(E519) -> 2025 | G519: =TEXT(E519,"MMMM") -> June | H519: =TEXT(E519,"YYYY-MM") -> 2025-06 | I519: =TODAY() - DATEVALUE(LEFT(D519,10)) -> 105 | J519: UCEPL07qzVsOcHd3sMUws65g | K519: Trakin Tech | L519: ['vivo t4 ultra', 'vivo t4 ultra review', 'vivo t4 ultra price in india', 'vivo t4 ultra unboxing', 'vivo t4 ultra 5g', 'vivo t4 ultra specification', 'vivo t4 ultra specs', 't4 ultra vivo', 'vivo t4 ultra buy or not', 'vivo t4 ultra comparison', 'vivo t4 ultra price', 'vivo t4 ultra camera test', 'vivo t4 ultra 5g unboxing', 'vivo t4 ultra vs', 'vivo t4 ultra first look', 'vivo t4 ultra vs vivo v50', 'vivo v50 vs vivo t4 ultra', 'vivo t4 ultra trakintech', 'best vivo under 35000', 't4 ultra', 'vivo v50 pro'] | M519: 28 | N519: =VLOOKUP(M519, CategoryMap!$A$2:$B$100, 2, FALSE) -> Science & Technology | O519: 873493 | P519: 31376 | Q519: 1621 | R519: =IF(O519=0, 0, (P519 + Q519) / O519) -> 0.037775918 | S519: 742 | T519: =IF(S519<=60, "Short", "Long") -> Long
A520: UlIU5LRMY6w | B520: Instagram Important Settings ð... | C520: Hidden instagram settings Hidden instagram feature... | D520: 2025-06-04T10:30:31Z | E520: =DATEVALUE(LEFT(D520,10)) -> 45812 | F520: =YEAR(E520) -> 2025 | G520: =TEXT(E520,"MMMM") -> June | H520: =TEXT(E520,"YYYY-MM") -> 2025-06 | I520: =TODAY() - DATEVALUE(LEFT(D520,10)) -> 112 | J520: UCD0ixD6V_esLsn1B66tkNnw | K520: Everything_techie | L520: ['Instagram tricks', 'Instagram tips', 'Instagram hacks', 'Instagram settings', 'Instagram features', 'Android tricks', 'Android hacks', 'Iphone tricks', 'Iphone hacks', 'Ios hacks'] | M520: 24 | N520: =VLOOKUP(M520, CategoryMap!$A$2:$B$100, 2, FALSE) -> Entertainment | O520: 1207 | P520: 14 | Q520: 0 | R520: =IF(O520=0, 0, (P520 + Q520) / O520) -> 0.011599006 | S520: 42 | T520: =IF(S520<=60, "Short", "Long") -> Short
A521: FhyAQZsws6s | B521: #mobilephone #smartphone #ripa... | C521: No description available | D521: 2025-06-02T14:28:33Z | E521: =DATEVALUE(LEFT(D521,10)) -> 45810 | F521: =YEAR(E521) -> 2025 | G521: =TEXT(E521,"MMMM") -> June | H521: =TEXT(E521,"YYYY-MM") -> 2025-06 | I521: =TODAY() - DATEVALUE(LEFT(D521,10)) -> 114 | J521: UCo0mAi0FlYnlwhGf7BvIuVg | K521: sarik mobile parts shop | L521: ['thailand', 'surin', 'style', 'travel', 'day', 'asia', 'elephant', 'bangkok', 'elephantnature', 'asian', 'animal', 'wildlife', 'chiang', 'african', 'asia', 'park', 'safari', 'big', 'travel', 'minneriya', 'thailand grass', 'art', 'green', 'ivory', 'à¸Šà¹‰à¸²à¸‡', 'à¸—à¸­à¸‡à¹ƒà¸š', 'à¸žà¸¥à¸²à¸¢à¸—à¸­à¸‡à¹ƒà¸š', 'à¸«à¸™à¸¸à¹ˆà¸¡à¹€à¸ªà¸', 'à¹€à¸ªà¸', 'à¸«à¸™à¸¸à¹ˆà¹€à¸ªà¸', 'à¸žà¸¥à¸²à¸¢à¸«à¸™à¸¸à¹ˆà¸¡à¹€à¸ªà¸', 'à¸­à¸‡à¸„à¹Œà¸šà¸²à¸', 'à¸žà¸¥à¸²à¸¢à¸šà¸±à¸§à¸šà¸²à¸™', 'à¸šà¸±à¸§à¸šà¸²à¸™', 'à¸à¸­à¸¢à¸—à¸­à¸‡', 'à¸”à¸²à¸§à¸¡à¸‡à¸„à¸¥', 'banana'] | M521: 22 | N521: =VLOOKUP(M521, CategoryMap!$A$2:$B$100, 2, FALSE) -> People & Blogs | O521: 21563 | P521: 154 | Q521: 0 | R521: =IF(O521=0, 0, (P521 + Q521) / O521) -> 0.0071418634 | S521: 21 | T521: =IF(S521<=60, "Short", "Long") -> Short
A522: PTjz11lURxE | B522: Impossible Technologies You Ca... | C522: Welcome to Trending Machine â€” where inventions h... | D522: 2025-05-02T14:00:39Z | E522: =DATEVALUE(LEFT(D522,10)) -> 45779 | F522: =YEAR(E522) -> 2025 | G522: =TEXT(E522,"MMMM") -> May | H522: =TEXT(E522,"YYYY-MM") -> 2025-05 | I522: =TODAY() - DATEVALUE(LEFT(D522,10)) -> 145 | J522: UCCfpI5ggGDPkD0F0Qfsbdpw | K522: Trending Machine | L522: ['trending machine', 'amazing inventions', 'amazing inventions that are on another level', 'crazy vehicles', 'inventions', 'technology', 'another level', 'amazing inventions you should see', 'machines', 'satisfying video', 'the most satisfying videos', 'amazing tools', 'road inventions', 'next level tools', 'next level', 'tips and hacks', 'gadgets', 'compilation', 'inventions that changed the world', 'new level', 'inventors', 'satisfying', 'awesome tools', 'new inventions', 'most amazing inventions you need to see'] | M522: 22 | N522: =VLOOKUP(M522, CategoryMap!$A$2:$B$100, 2, FALSE) -> People & Blogs | O522: 523536 | P522: 4065 | Q522: 74 | R522: =IF(O522=0, 0, (P522 + Q522) / O522) -> 0.0079058556 | S522: 20 | T522: =IF(S522<=60, "Short", "Long") -> Short
A523: hRHQgU5obiQ | B523: I TRIED 7 COOL GADGETS FROM SH... | C523: I TRIED 7 COOL GADGETS FROM SHARK TANK #ujjwal #te... | D523: 2025-03-18T12:30:43Z | E523: =DATEVALUE(LEFT(D523,10)) -> 45734 | F523: =YEAR(E523) -> 2025 | G523: =TEXT(E523,"MMMM") -> March | H523: =TEXT(E523,"YYYY-MM") -> 2025-03 | I523: =TODAY() - DATEVALUE(LEFT(D523,10)) -> 190 | J523: UCs6EmLAT4lTWwCSJRgbbchQ | K523: TechShot | L523: ['best tech', 'gadgets', 'unboxing', 'amazing', 'useful', 'experiment', 'review', 'new', 'innovative', 'shark tank', 'shark tank india', 'future tech', 'cool', 'smart', 'smart living', 'smart gadgets', 'tech review', 'startup india', 'wearable tech', 'gaming', 'AI', 'made in india', 'digital india', 'ujjwal', 'technogamerz'] | M523: 28 | N523: =VLOOKUP(M523, CategoryMap!$A$2:$B$100, 2, FALSE) -> Science & Technology | O523: 4358841 | P523: 99282 | Q523: 8985 | R523: =IF(O523=0, 0, (P523 + Q523) / O523) -> 0.024838483 | S523: 2294 | T523: =IF(S523<=60, "Short", "Long") -> Long
A524: pCqKf1r79m8 | B524: polythene urine #facts #viralv... | C524: No description available | D524: 2025-05-28T11:21:41Z | E524: =DATEVALUE(LEFT(D524,10)) -> 45805 | F524: =YEAR(E524) -> 2025 | G524: =TEXT(E524,"MMMM") -> May | H524: =TEXT(E524,"YYYY-MM") -> 2025-05 | I524: =TODAY() - DATEVALUE(LEFT(D524,10)) -> 119 | J524: UCXJ3BsorN7sn1JnrudJJj8Q | K524: knowledgible facts | L524: ['thailand', 'surin', 'style', 'travel', 'day', 'asia', 'elephant', 'bangkok', 'elephantnature', 'asian', 'animal', 'wildlife', 'chiang', 'african', 'asia', 'park', 'safari', 'big', 'travel', 'minneriya', 'thailand grass', 'art', 'green', 'ivory', 'à¸Šà¹‰à¸²à¸‡', 'à¸—à¸­à¸‡à¹ƒà¸š', 'à¸žà¸¥à¸²à¸¢à¸—à¸­à¸‡à¹ƒà¸š', 'à¸«à¸™à¸¸à¹ˆà¸¡à¹€à¸ªà¸', 'à¹€à¸ªà¸', 'à¸«à¸™à¸¸à¹ˆà¹€à¸ªà¸', 'à¸žà¸¥à¸²à¸¢à¸«à¸™à¸¸à¹ˆà¸¡à¹€à¸ªà¸', 'à¸­à¸‡à¸„à¹Œà¸šà¸²à¸', 'à¸žà¸¥à¸²à¸¢à¸šà¸±à¸§à¸šà¸²à¸™', 'à¸šà¸±à¸§à¸šà¸²à¸™', 'à¸à¸­à¸¢à¸—à¸­à¸‡', 'à¸”à¸²à¸§à¸¡à¸‡à¸„à¸¥', 'banana'] | M524: 28 | N524: =VLOOKUP(M524, CategoryMap!$A$2:$B$100, 2, FALSE) -> Science & Technology | O524: 5331 | P524: 18 | Q524: 0 | R524: =IF(O524=0, 0, (P524 + Q524) / O524) -> 0.0033764772 | S524: 56 | T524: =IF(S524<=60, "Short", "Long") -> Short
A525: H0vfYzwh3kM | B525: Lost Your Phone? Do This ASAP!... | C525: Lost Your Phone? Do This ASAP! #gadgets360 #androi... | D525: 2025-05-04T13:23:16Z | E525: =DATEVALUE(LEFT(D525,10)) -> 45781 | F525: =YEAR(E525) -> 2025 | G525: =TEXT(E525,"MMMM") -> May | H525: =TEXT(E525,"YYYY-MM") -> 2025-05 | I525: =TODAY() - DATEVALUE(LEFT(D525,10)) -> 143 | J525: UCx5e1u7BX0aKwEj3sdYXdXg | K525: Gadgets 360 | L525: ['how to know if your phone is hacked', 'phone spy', 'phone spying', 'android phone', 'phone tracking', 'phone monitoring', '#lostphone', 'how to tell if your iphone is hacked', '#phonesecurity', 'iphone', 'iphone 15', 'iphone 12', 'iphone 13', 'iphone fix', 'how to use find my iphone', 'iphone tips', 'how to study', 'iphone 15 pro', 'iphone hacks', 'what to do if i lose my iphone', 'how to check if your iphone has been hacked', 'iphone repair', 'how to spend money correctly', '#findmyiphone'] | M525: 26 | N525: =VLOOKUP(M525, CategoryMap!$A$2:$B$100, 2, FALSE) -> Howto & Style | O525: 5091 | P525: 39 | Q525: 0 | R525: =IF(O525=0, 0, (P525 + Q525) / O525) -> 0.0076605775 | S525: 39 | T525: =IF(S525<=60, "Short", "Long") -> Short
A526: 4aZDNO7c8Z8 | B526: Why Investors Are Piling into ... | C526: Africaâ€™s tech startups raised a record $5 billio... | D526: 2022-04-07T13:27:33Z | E526: =DATEVALUE(LEFT(D526,10)) -> 44658 | F526: =YEAR(E526) -> 2022 | G526: =TEXT(E526,"MMMM") -> April | H526: =TEXT(E526,"YYYY-MM") -> 2022-04 | I526: =TODAY() - DATEVALUE(LEFT(D526,10)) -> 1266 | J526: UCUMZ7gohGI9HcU9VNsr2FJQ | K526: Bloomberg Originals | L526: ['News', 'bloomberg', 'quicktake', 'business', 'bloomberg quicktake', 'quicktake originals', 'bloomberg\nquicktake by bloomberg', 'documentary', 'mini documentary', 'mini doc', 'doc', 'us news', 'world news', 'finance', 'science', 'africa+', 'tech startups', 'investment', 'US', 'China', 'flutterwave', 'sendy', 'ihub', 'mopesa'] | M526: 25 | N526: =VLOOKUP(M526, CategoryMap!$A$2:$B$100, 2, FALSE) -> News & Politics | O526: 344551 | P526: 7548 | Q526: 465 | R526: =IF(O526=0, 0, (P526 + Q526) / O526) -> 0.023256354 | S526: 967 | T526: =IF(S526<=60, "Short", "Long") -> Long
...

Sheet Pivot Tables
A3: Row Labels | B3: Sum of view_count
A4: Long | B4: 9.7515161e+08
A5: Short | B5: 3.8339307e+09
A6: Grand Total | B6: 4.8090823e+09
A13: Row Labels | B13: Sum of like_count | C13: Sum of comment_count
A14: zFT3YuNnF6g | B14: 3061219 | C14: 11926
A15: OcuYIlrG7ao | B15: 2964109 | C15: 14876
A16: IPhARlUO6NA | B16: 4421091 | C16: 8794
A17: 1Nef8LPO-jo | B17: 4178447 | C17: 6378
A18: -055GvEU7f0 | B18: 4130446 | C18: 7065
A19: Grand Total | B19: 18755312 | C19: 49039
A25: Row Labels | B25: Sum of view_count
A26: Worlds smallest 4K headset ðŸ˜... | B26: 259311517
A27: This is future technology 2d a... | B27: 246090760
A28: New Science Project #shorts #s... | B28: 179327926
A29: Free motion setup in progress ... | B29: 139303650
A30: 50 Cent - Ayo Technology (Offi... | B30: 343758991
A31: Grand Total | B31: 1167792844
A40: Row Labels | B40: Average of duration_seconds
A41: Long | B41: 987.15676
A42: Short | B42: 29.598997
A43: Grand Total | B43: 332.93493
A49: Row Labels | B49: Average of engagement_rate | C49: Sum of view_count
A50: Pwt Tech | B50: 697.00195 | C50: 312
A51: Mx Mobile | B51: 54.762853 | C51: 4007
A52: F4 Faiz | B52: 182.74421 | C52: 1190
A53: Grand Total | B53: 311.503 | C53: 5509
A61: Row Labels | B61: Count of video_id
A62: Autos & Vehicles | B62: 6
A63: Comedy | B63: 20
A64: Education | B64: 53
A65: Entertainment | B65: 50
A66: Film & Animation | B66: 4
A67: Gaming | B67: 19
A68: Howto & Style | B68: 10
A69: Music | B69: 13
A70: News & Politics | B70: 16
A71: Nonprofits & Activism | B71: 2
A72: People & Blogs | B72: 93
A73: Pets & Animals | B73: 7
...

Sheet Dashboard
